[2020-03-24 20:14:21 +0800] [15251] [INFO] Starting gunicorn 20.0.4
[2020-03-24 20:14:21 +0800] [15251] [INFO] Listening at: http://127.0.0.1:8080 (15251)
[2020-03-24 20:14:21 +0800] [15251] [INFO] Using worker: sync
[2020-03-24 20:14:21 +0800] [15254] [INFO] Booting worker with pid: 15254
[2020-03-24 20:19:07 +0800] [15272] [INFO] Booting worker with pid: 15272
[2020-03-24 20:20:07 +0800] [15272] [INFO] Parent changed, shutting down: <Worker 15272>
[2020-03-24 20:20:07 +0800] [15272] [INFO] Worker exiting (pid: 15272)
[2020-03-24 20:29:22 +0800] [1398] [INFO] Starting gunicorn 20.0.4
[2020-03-24 20:29:22 +0800] [1398] [INFO] Listening at: http://127.0.0.1:8080 (1398)
[2020-03-24 20:29:22 +0800] [1398] [INFO] Using worker: sync
[2020-03-24 20:29:22 +0800] [1401] [INFO] Booting worker with pid: 1401
[2020-03-24 21:01:46 +0800] [1571] [INFO] Starting gunicorn 20.0.4
[2020-03-24 21:01:46 +0800] [1571] [INFO] Listening at: http://0.0.0.0:8080 (1571)
[2020-03-24 21:01:46 +0800] [1571] [INFO] Using worker: sync
[2020-03-24 21:01:46 +0800] [1574] [INFO] Booting worker with pid: 1574
[2020-03-24 21:09:08 +0800] [1574] [INFO] Parent changed, shutting down: <Worker 1574>
[2020-03-24 21:09:08 +0800] [1574] [INFO] Worker exiting (pid: 1574)
[2020-03-24 21:12:11 +0800] [1684] [INFO] Starting gunicorn 20.0.4
[2020-03-24 21:12:11 +0800] [1684] [INFO] Listening at: http://0.0.0.0:8080 (1684)
[2020-03-24 21:12:11 +0800] [1684] [INFO] Using worker: sync
[2020-03-24 21:12:11 +0800] [1687] [INFO] Booting worker with pid: 1687
[2020-03-24 21:23:23,375] ERROR in app: Exception on /api/upload [POST]
Traceback (most recent call last):
  File "/root/anaconda3/envs/faceexpression_reco/lib/python3.6/site-packages/flask/app.py", line 2446, in wsgi_app
    response = self.full_dispatch_request()
  File "/root/anaconda3/envs/faceexpression_reco/lib/python3.6/site-packages/flask/app.py", line 1951, in full_dispatch_request
    rv = self.handle_user_exception(e)
  File "/root/anaconda3/envs/faceexpression_reco/lib/python3.6/site-packages/flask/app.py", line 1820, in handle_user_exception
    reraise(exc_type, exc_value, tb)
  File "/root/anaconda3/envs/faceexpression_reco/lib/python3.6/site-packages/flask/_compat.py", line 39, in reraise
    raise value
  File "/root/anaconda3/envs/faceexpression_reco/lib/python3.6/site-packages/flask/app.py", line 1949, in full_dispatch_request
    rv = self.dispatch_request()
  File "/root/anaconda3/envs/faceexpression_reco/lib/python3.6/site-packages/flask/app.py", line 1935, in dispatch_request
    return self.view_functions[rule.endpoint](**req.view_args)
  File "/home/iotlab/receive/receive_service.py", line 68, in uplaod_file
    result_response = js.loads(report.content)
  File "/root/anaconda3/envs/faceexpression_reco/lib/python3.6/json/__init__.py", line 354, in loads
    return _default_decoder.decode(s)
  File "/root/anaconda3/envs/faceexpression_reco/lib/python3.6/json/decoder.py", line 339, in decode
    obj, end = self.raw_decode(s, idx=_w(s, 0).end())
  File "/root/anaconda3/envs/faceexpression_reco/lib/python3.6/json/decoder.py", line 357, in raw_decode
    raise JSONDecodeError("Expecting value", s, err.value) from None
json.decoder.JSONDecodeError: Expecting value: line 1 column 1 (char 0)
[2020-03-24 21:23:38,085] ERROR in app: Exception on /api/upload [POST]
Traceback (most recent call last):
  File "/root/anaconda3/envs/faceexpression_reco/lib/python3.6/site-packages/flask/app.py", line 2446, in wsgi_app
    response = self.full_dispatch_request()
  File "/root/anaconda3/envs/faceexpression_reco/lib/python3.6/site-packages/flask/app.py", line 1951, in full_dispatch_request
    rv = self.handle_user_exception(e)
  File "/root/anaconda3/envs/faceexpression_reco/lib/python3.6/site-packages/flask/app.py", line 1820, in handle_user_exception
    reraise(exc_type, exc_value, tb)
  File "/root/anaconda3/envs/faceexpression_reco/lib/python3.6/site-packages/flask/_compat.py", line 39, in reraise
    raise value
  File "/root/anaconda3/envs/faceexpression_reco/lib/python3.6/site-packages/flask/app.py", line 1949, in full_dispatch_request
    rv = self.dispatch_request()
  File "/root/anaconda3/envs/faceexpression_reco/lib/python3.6/site-packages/flask/app.py", line 1935, in dispatch_request
    return self.view_functions[rule.endpoint](**req.view_args)
  File "/home/iotlab/receive/receive_service.py", line 68, in uplaod_file
    result_response = js.loads(report.content)
  File "/root/anaconda3/envs/faceexpression_reco/lib/python3.6/json/__init__.py", line 354, in loads
    return _default_decoder.decode(s)
  File "/root/anaconda3/envs/faceexpression_reco/lib/python3.6/json/decoder.py", line 339, in decode
    obj, end = self.raw_decode(s, idx=_w(s, 0).end())
  File "/root/anaconda3/envs/faceexpression_reco/lib/python3.6/json/decoder.py", line 357, in raw_decode
    raise JSONDecodeError("Expecting value", s, err.value) from None
json.decoder.JSONDecodeError: Expecting value: line 1 column 1 (char 0)
[2020-03-24 21:24:30,275] ERROR in app: Exception on /api/upload [POST]
Traceback (most recent call last):
  File "/root/anaconda3/envs/faceexpression_reco/lib/python3.6/site-packages/flask/app.py", line 2446, in wsgi_app
    response = self.full_dispatch_request()
  File "/root/anaconda3/envs/faceexpression_reco/lib/python3.6/site-packages/flask/app.py", line 1951, in full_dispatch_request
    rv = self.handle_user_exception(e)
  File "/root/anaconda3/envs/faceexpression_reco/lib/python3.6/site-packages/flask/app.py", line 1820, in handle_user_exception
    reraise(exc_type, exc_value, tb)
  File "/root/anaconda3/envs/faceexpression_reco/lib/python3.6/site-packages/flask/_compat.py", line 39, in reraise
    raise value
  File "/root/anaconda3/envs/faceexpression_reco/lib/python3.6/site-packages/flask/app.py", line 1949, in full_dispatch_request
    rv = self.dispatch_request()
  File "/root/anaconda3/envs/faceexpression_reco/lib/python3.6/site-packages/flask/app.py", line 1935, in dispatch_request
    return self.view_functions[rule.endpoint](**req.view_args)
  File "/home/iotlab/receive/receive_service.py", line 68, in uplaod_file
    result_response = js.loads(report.content)
  File "/root/anaconda3/envs/faceexpression_reco/lib/python3.6/json/__init__.py", line 354, in loads
    return _default_decoder.decode(s)
  File "/root/anaconda3/envs/faceexpression_reco/lib/python3.6/json/decoder.py", line 339, in decode
    obj, end = self.raw_decode(s, idx=_w(s, 0).end())
  File "/root/anaconda3/envs/faceexpression_reco/lib/python3.6/json/decoder.py", line 357, in raw_decode
    raise JSONDecodeError("Expecting value", s, err.value) from None
json.decoder.JSONDecodeError: Expecting value: line 1 column 1 (char 0)
[2020-03-24 21:26:12,861] ERROR in app: Exception on /api/upload [POST]
Traceback (most recent call last):
  File "/root/anaconda3/envs/faceexpression_reco/lib/python3.6/site-packages/flask/app.py", line 2446, in wsgi_app
    response = self.full_dispatch_request()
  File "/root/anaconda3/envs/faceexpression_reco/lib/python3.6/site-packages/flask/app.py", line 1951, in full_dispatch_request
    rv = self.handle_user_exception(e)
  File "/root/anaconda3/envs/faceexpression_reco/lib/python3.6/site-packages/flask/app.py", line 1820, in handle_user_exception
    reraise(exc_type, exc_value, tb)
  File "/root/anaconda3/envs/faceexpression_reco/lib/python3.6/site-packages/flask/_compat.py", line 39, in reraise
    raise value
  File "/root/anaconda3/envs/faceexpression_reco/lib/python3.6/site-packages/flask/app.py", line 1949, in full_dispatch_request
    rv = self.dispatch_request()
  File "/root/anaconda3/envs/faceexpression_reco/lib/python3.6/site-packages/flask/app.py", line 1935, in dispatch_request
    return self.view_functions[rule.endpoint](**req.view_args)
  File "/home/iotlab/receive/receive_service.py", line 68, in uplaod_file
    result_response = js.loads(report.content)
  File "/root/anaconda3/envs/faceexpression_reco/lib/python3.6/json/__init__.py", line 354, in loads
    return _default_decoder.decode(s)
  File "/root/anaconda3/envs/faceexpression_reco/lib/python3.6/json/decoder.py", line 339, in decode
    obj, end = self.raw_decode(s, idx=_w(s, 0).end())
  File "/root/anaconda3/envs/faceexpression_reco/lib/python3.6/json/decoder.py", line 357, in raw_decode
    raise JSONDecodeError("Expecting value", s, err.value) from None
json.decoder.JSONDecodeError: Expecting value: line 1 column 1 (char 0)
[2020-03-24 21:27:40,374] ERROR in app: Exception on /api/upload [POST]
Traceback (most recent call last):
  File "/root/anaconda3/envs/faceexpression_reco/lib/python3.6/site-packages/flask/app.py", line 2446, in wsgi_app
    response = self.full_dispatch_request()
  File "/root/anaconda3/envs/faceexpression_reco/lib/python3.6/site-packages/flask/app.py", line 1951, in full_dispatch_request
    rv = self.handle_user_exception(e)
  File "/root/anaconda3/envs/faceexpression_reco/lib/python3.6/site-packages/flask/app.py", line 1820, in handle_user_exception
    reraise(exc_type, exc_value, tb)
  File "/root/anaconda3/envs/faceexpression_reco/lib/python3.6/site-packages/flask/_compat.py", line 39, in reraise
    raise value
  File "/root/anaconda3/envs/faceexpression_reco/lib/python3.6/site-packages/flask/app.py", line 1949, in full_dispatch_request
    rv = self.dispatch_request()
  File "/root/anaconda3/envs/faceexpression_reco/lib/python3.6/site-packages/flask/app.py", line 1935, in dispatch_request
    return self.view_functions[rule.endpoint](**req.view_args)
  File "/home/iotlab/receive/receive_service.py", line 68, in uplaod_file
    result_response = js.loads(report.content)
  File "/root/anaconda3/envs/faceexpression_reco/lib/python3.6/json/__init__.py", line 354, in loads
    return _default_decoder.decode(s)
  File "/root/anaconda3/envs/faceexpression_reco/lib/python3.6/json/decoder.py", line 339, in decode
    obj, end = self.raw_decode(s, idx=_w(s, 0).end())
  File "/root/anaconda3/envs/faceexpression_reco/lib/python3.6/json/decoder.py", line 357, in raw_decode
    raise JSONDecodeError("Expecting value", s, err.value) from None
json.decoder.JSONDecodeError: Expecting value: line 1 column 1 (char 0)
[2020-03-24 21:27:55,707] ERROR in app: Exception on /api/upload [POST]
Traceback (most recent call last):
  File "/root/anaconda3/envs/faceexpression_reco/lib/python3.6/site-packages/flask/app.py", line 2446, in wsgi_app
    response = self.full_dispatch_request()
  File "/root/anaconda3/envs/faceexpression_reco/lib/python3.6/site-packages/flask/app.py", line 1951, in full_dispatch_request
    rv = self.handle_user_exception(e)
  File "/root/anaconda3/envs/faceexpression_reco/lib/python3.6/site-packages/flask/app.py", line 1820, in handle_user_exception
    reraise(exc_type, exc_value, tb)
  File "/root/anaconda3/envs/faceexpression_reco/lib/python3.6/site-packages/flask/_compat.py", line 39, in reraise
    raise value
  File "/root/anaconda3/envs/faceexpression_reco/lib/python3.6/site-packages/flask/app.py", line 1949, in full_dispatch_request
    rv = self.dispatch_request()
  File "/root/anaconda3/envs/faceexpression_reco/lib/python3.6/site-packages/flask/app.py", line 1935, in dispatch_request
    return self.view_functions[rule.endpoint](**req.view_args)
  File "/home/iotlab/receive/receive_service.py", line 68, in uplaod_file
    result_response = js.loads(report.content)
  File "/root/anaconda3/envs/faceexpression_reco/lib/python3.6/json/__init__.py", line 354, in loads
    return _default_decoder.decode(s)
  File "/root/anaconda3/envs/faceexpression_reco/lib/python3.6/json/decoder.py", line 339, in decode
    obj, end = self.raw_decode(s, idx=_w(s, 0).end())
  File "/root/anaconda3/envs/faceexpression_reco/lib/python3.6/json/decoder.py", line 357, in raw_decode
    raise JSONDecodeError("Expecting value", s, err.value) from None
json.decoder.JSONDecodeError: Expecting value: line 1 column 1 (char 0)
[2020-03-24 21:32:08 +0800] [1684] [CRITICAL] WORKER TIMEOUT (pid:1687)
[2020-03-24 21:32:08 +0800] [1687] [INFO] Worker exiting (pid: 1687)
[2020-03-24 21:32:08 +0800] [1863] [INFO] Booting worker with pid: 1863
[2020-03-24 21:34:30,692] ERROR in app: Exception on /api/upload [POST]
Traceback (most recent call last):
  File "/root/anaconda3/envs/faceexpression_reco/lib/python3.6/site-packages/flask/app.py", line 2446, in wsgi_app
    response = self.full_dispatch_request()
  File "/root/anaconda3/envs/faceexpression_reco/lib/python3.6/site-packages/flask/app.py", line 1951, in full_dispatch_request
    rv = self.handle_user_exception(e)
  File "/root/anaconda3/envs/faceexpression_reco/lib/python3.6/site-packages/flask/app.py", line 1820, in handle_user_exception
    reraise(exc_type, exc_value, tb)
  File "/root/anaconda3/envs/faceexpression_reco/lib/python3.6/site-packages/flask/_compat.py", line 39, in reraise
    raise value
  File "/root/anaconda3/envs/faceexpression_reco/lib/python3.6/site-packages/flask/app.py", line 1949, in full_dispatch_request
    rv = self.dispatch_request()
  File "/root/anaconda3/envs/faceexpression_reco/lib/python3.6/site-packages/flask/app.py", line 1935, in dispatch_request
    return self.view_functions[rule.endpoint](**req.view_args)
  File "/home/iotlab/receive/receive_service.py", line 68, in uplaod_file
    result_response = js.loads(report.content)
  File "/root/anaconda3/envs/faceexpression_reco/lib/python3.6/json/__init__.py", line 354, in loads
    return _default_decoder.decode(s)
  File "/root/anaconda3/envs/faceexpression_reco/lib/python3.6/json/decoder.py", line 339, in decode
    obj, end = self.raw_decode(s, idx=_w(s, 0).end())
  File "/root/anaconda3/envs/faceexpression_reco/lib/python3.6/json/decoder.py", line 357, in raw_decode
    raise JSONDecodeError("Expecting value", s, err.value) from None
json.decoder.JSONDecodeError: Expecting value: line 1 column 1 (char 0)
[2020-03-24 21:35:25,708] ERROR in app: Exception on /api/upload [POST]
Traceback (most recent call last):
  File "/root/anaconda3/envs/faceexpression_reco/lib/python3.6/site-packages/flask/app.py", line 2446, in wsgi_app
    response = self.full_dispatch_request()
  File "/root/anaconda3/envs/faceexpression_reco/lib/python3.6/site-packages/flask/app.py", line 1951, in full_dispatch_request
    rv = self.handle_user_exception(e)
  File "/root/anaconda3/envs/faceexpression_reco/lib/python3.6/site-packages/flask/app.py", line 1820, in handle_user_exception
    reraise(exc_type, exc_value, tb)
  File "/root/anaconda3/envs/faceexpression_reco/lib/python3.6/site-packages/flask/_compat.py", line 39, in reraise
    raise value
  File "/root/anaconda3/envs/faceexpression_reco/lib/python3.6/site-packages/flask/app.py", line 1949, in full_dispatch_request
    rv = self.dispatch_request()
  File "/root/anaconda3/envs/faceexpression_reco/lib/python3.6/site-packages/flask/app.py", line 1935, in dispatch_request
    return self.view_functions[rule.endpoint](**req.view_args)
  File "/home/iotlab/receive/receive_service.py", line 68, in uplaod_file
    result_response = js.loads(report.content)
  File "/root/anaconda3/envs/faceexpression_reco/lib/python3.6/json/__init__.py", line 354, in loads
    return _default_decoder.decode(s)
  File "/root/anaconda3/envs/faceexpression_reco/lib/python3.6/json/decoder.py", line 339, in decode
    obj, end = self.raw_decode(s, idx=_w(s, 0).end())
  File "/root/anaconda3/envs/faceexpression_reco/lib/python3.6/json/decoder.py", line 357, in raw_decode
    raise JSONDecodeError("Expecting value", s, err.value) from None
json.decoder.JSONDecodeError: Expecting value: line 1 column 1 (char 0)
[2020-03-24 21:35:48,512] ERROR in app: Exception on /api/upload [POST]
Traceback (most recent call last):
  File "/root/anaconda3/envs/faceexpression_reco/lib/python3.6/site-packages/flask/app.py", line 2446, in wsgi_app
    response = self.full_dispatch_request()
  File "/root/anaconda3/envs/faceexpression_reco/lib/python3.6/site-packages/flask/app.py", line 1951, in full_dispatch_request
    rv = self.handle_user_exception(e)
  File "/root/anaconda3/envs/faceexpression_reco/lib/python3.6/site-packages/flask/app.py", line 1820, in handle_user_exception
    reraise(exc_type, exc_value, tb)
  File "/root/anaconda3/envs/faceexpression_reco/lib/python3.6/site-packages/flask/_compat.py", line 39, in reraise
    raise value
  File "/root/anaconda3/envs/faceexpression_reco/lib/python3.6/site-packages/flask/app.py", line 1949, in full_dispatch_request
    rv = self.dispatch_request()
  File "/root/anaconda3/envs/faceexpression_reco/lib/python3.6/site-packages/flask/app.py", line 1935, in dispatch_request
    return self.view_functions[rule.endpoint](**req.view_args)
  File "/home/iotlab/receive/receive_service.py", line 68, in uplaod_file
    result_response = js.loads(report.content)
  File "/root/anaconda3/envs/faceexpression_reco/lib/python3.6/json/__init__.py", line 354, in loads
    return _default_decoder.decode(s)
  File "/root/anaconda3/envs/faceexpression_reco/lib/python3.6/json/decoder.py", line 339, in decode
    obj, end = self.raw_decode(s, idx=_w(s, 0).end())
  File "/root/anaconda3/envs/faceexpression_reco/lib/python3.6/json/decoder.py", line 357, in raw_decode
    raise JSONDecodeError("Expecting value", s, err.value) from None
json.decoder.JSONDecodeError: Expecting value: line 1 column 1 (char 0)
[2020-03-24 21:36:55,590] ERROR in app: Exception on /api/upload [POST]
Traceback (most recent call last):
  File "/root/anaconda3/envs/faceexpression_reco/lib/python3.6/site-packages/flask/app.py", line 2446, in wsgi_app
    response = self.full_dispatch_request()
  File "/root/anaconda3/envs/faceexpression_reco/lib/python3.6/site-packages/flask/app.py", line 1951, in full_dispatch_request
    rv = self.handle_user_exception(e)
  File "/root/anaconda3/envs/faceexpression_reco/lib/python3.6/site-packages/flask/app.py", line 1820, in handle_user_exception
    reraise(exc_type, exc_value, tb)
  File "/root/anaconda3/envs/faceexpression_reco/lib/python3.6/site-packages/flask/_compat.py", line 39, in reraise
    raise value
  File "/root/anaconda3/envs/faceexpression_reco/lib/python3.6/site-packages/flask/app.py", line 1949, in full_dispatch_request
    rv = self.dispatch_request()
  File "/root/anaconda3/envs/faceexpression_reco/lib/python3.6/site-packages/flask/app.py", line 1935, in dispatch_request
    return self.view_functions[rule.endpoint](**req.view_args)
  File "/home/iotlab/receive/receive_service.py", line 68, in uplaod_file
    result_response = js.loads(report.content)
  File "/root/anaconda3/envs/faceexpression_reco/lib/python3.6/json/__init__.py", line 354, in loads
    return _default_decoder.decode(s)
  File "/root/anaconda3/envs/faceexpression_reco/lib/python3.6/json/decoder.py", line 339, in decode
    obj, end = self.raw_decode(s, idx=_w(s, 0).end())
  File "/root/anaconda3/envs/faceexpression_reco/lib/python3.6/json/decoder.py", line 357, in raw_decode
    raise JSONDecodeError("Expecting value", s, err.value) from None
json.decoder.JSONDecodeError: Expecting value: line 1 column 1 (char 0)
[2020-03-24 21:37:38,390] ERROR in app: Exception on /api/upload [POST]
Traceback (most recent call last):
  File "/root/anaconda3/envs/faceexpression_reco/lib/python3.6/site-packages/flask/app.py", line 2446, in wsgi_app
    response = self.full_dispatch_request()
  File "/root/anaconda3/envs/faceexpression_reco/lib/python3.6/site-packages/flask/app.py", line 1951, in full_dispatch_request
    rv = self.handle_user_exception(e)
  File "/root/anaconda3/envs/faceexpression_reco/lib/python3.6/site-packages/flask/app.py", line 1820, in handle_user_exception
    reraise(exc_type, exc_value, tb)
  File "/root/anaconda3/envs/faceexpression_reco/lib/python3.6/site-packages/flask/_compat.py", line 39, in reraise
    raise value
  File "/root/anaconda3/envs/faceexpression_reco/lib/python3.6/site-packages/flask/app.py", line 1949, in full_dispatch_request
    rv = self.dispatch_request()
  File "/root/anaconda3/envs/faceexpression_reco/lib/python3.6/site-packages/flask/app.py", line 1935, in dispatch_request
    return self.view_functions[rule.endpoint](**req.view_args)
  File "/home/iotlab/receive/receive_service.py", line 68, in uplaod_file
    result_response = js.loads(report.content)
  File "/root/anaconda3/envs/faceexpression_reco/lib/python3.6/json/__init__.py", line 354, in loads
    return _default_decoder.decode(s)
  File "/root/anaconda3/envs/faceexpression_reco/lib/python3.6/json/decoder.py", line 339, in decode
    obj, end = self.raw_decode(s, idx=_w(s, 0).end())
  File "/root/anaconda3/envs/faceexpression_reco/lib/python3.6/json/decoder.py", line 357, in raw_decode
    raise JSONDecodeError("Expecting value", s, err.value) from None
json.decoder.JSONDecodeError: Expecting value: line 1 column 1 (char 0)
[2020-03-24 21:43:59 +0800] [1684] [CRITICAL] WORKER TIMEOUT (pid:1863)
[2020-03-24 21:43:59 +0800] [1863] [INFO] Worker exiting (pid: 1863)
[2020-03-24 21:43:59 +0800] [1887] [INFO] Booting worker with pid: 1887
[2020-03-24 21:52:26,784] ERROR in app: Exception on /api/upload [POST]
Traceback (most recent call last):
  File "/root/anaconda3/envs/faceexpression_reco/lib/python3.6/site-packages/flask/app.py", line 2446, in wsgi_app
    response = self.full_dispatch_request()
  File "/root/anaconda3/envs/faceexpression_reco/lib/python3.6/site-packages/flask/app.py", line 1951, in full_dispatch_request
    rv = self.handle_user_exception(e)
  File "/root/anaconda3/envs/faceexpression_reco/lib/python3.6/site-packages/flask/app.py", line 1820, in handle_user_exception
    reraise(exc_type, exc_value, tb)
  File "/root/anaconda3/envs/faceexpression_reco/lib/python3.6/site-packages/flask/_compat.py", line 39, in reraise
    raise value
  File "/root/anaconda3/envs/faceexpression_reco/lib/python3.6/site-packages/flask/app.py", line 1949, in full_dispatch_request
    rv = self.dispatch_request()
  File "/root/anaconda3/envs/faceexpression_reco/lib/python3.6/site-packages/flask/app.py", line 1935, in dispatch_request
    return self.view_functions[rule.endpoint](**req.view_args)
  File "/home/iotlab/receive/receive_service.py", line 68, in uplaod_file
    result_response = js.loads(report.content)
  File "/root/anaconda3/envs/faceexpression_reco/lib/python3.6/json/__init__.py", line 354, in loads
    return _default_decoder.decode(s)
  File "/root/anaconda3/envs/faceexpression_reco/lib/python3.6/json/decoder.py", line 339, in decode
    obj, end = self.raw_decode(s, idx=_w(s, 0).end())
  File "/root/anaconda3/envs/faceexpression_reco/lib/python3.6/json/decoder.py", line 357, in raw_decode
    raise JSONDecodeError("Expecting value", s, err.value) from None
json.decoder.JSONDecodeError: Expecting value: line 1 column 1 (char 0)
[2020-03-24 22:04:16,521] ERROR in app: Exception on /api/upload [POST]
Traceback (most recent call last):
  File "/root/anaconda3/envs/faceexpression_reco/lib/python3.6/site-packages/flask/app.py", line 2446, in wsgi_app
    response = self.full_dispatch_request()
  File "/root/anaconda3/envs/faceexpression_reco/lib/python3.6/site-packages/flask/app.py", line 1951, in full_dispatch_request
    rv = self.handle_user_exception(e)
  File "/root/anaconda3/envs/faceexpression_reco/lib/python3.6/site-packages/flask/app.py", line 1820, in handle_user_exception
    reraise(exc_type, exc_value, tb)
  File "/root/anaconda3/envs/faceexpression_reco/lib/python3.6/site-packages/flask/_compat.py", line 39, in reraise
    raise value
  File "/root/anaconda3/envs/faceexpression_reco/lib/python3.6/site-packages/flask/app.py", line 1949, in full_dispatch_request
    rv = self.dispatch_request()
  File "/root/anaconda3/envs/faceexpression_reco/lib/python3.6/site-packages/flask/app.py", line 1935, in dispatch_request
    return self.view_functions[rule.endpoint](**req.view_args)
  File "/home/iotlab/receive/receive_service.py", line 99, in uplaod_file
    return result
UnboundLocalError: local variable 'result' referenced before assignment
[2020-03-24 22:12:02,325] ERROR in app: Exception on /api/upload [POST]
Traceback (most recent call last):
  File "/root/anaconda3/envs/faceexpression_reco/lib/python3.6/site-packages/flask/app.py", line 2446, in wsgi_app
    response = self.full_dispatch_request()
  File "/root/anaconda3/envs/faceexpression_reco/lib/python3.6/site-packages/flask/app.py", line 1951, in full_dispatch_request
    rv = self.handle_user_exception(e)
  File "/root/anaconda3/envs/faceexpression_reco/lib/python3.6/site-packages/flask/app.py", line 1820, in handle_user_exception
    reraise(exc_type, exc_value, tb)
  File "/root/anaconda3/envs/faceexpression_reco/lib/python3.6/site-packages/flask/_compat.py", line 39, in reraise
    raise value
  File "/root/anaconda3/envs/faceexpression_reco/lib/python3.6/site-packages/flask/app.py", line 1949, in full_dispatch_request
    rv = self.dispatch_request()
  File "/root/anaconda3/envs/faceexpression_reco/lib/python3.6/site-packages/flask/app.py", line 1935, in dispatch_request
    return self.view_functions[rule.endpoint](**req.view_args)
  File "/home/iotlab/receive/receive_service.py", line 99, in uplaod_file
    return result
UnboundLocalError: local variable 'result' referenced before assignment
[2020-03-24 22:19:13 +0800] [2081] [INFO] Starting gunicorn 20.0.4
[2020-03-24 22:19:13 +0800] [2081] [INFO] Listening at: http://0.0.0.0:8080 (2081)
[2020-03-24 22:19:13 +0800] [2081] [INFO] Using worker: sync
[2020-03-24 22:19:13 +0800] [2084] [INFO] Booting worker with pid: 2084
[2020-03-24 22:38:56,455] ERROR in app: Exception on /api/upload [POST]
Traceback (most recent call last):
  File "/root/anaconda3/envs/faceexpression_reco/lib/python3.6/site-packages/flask/app.py", line 2446, in wsgi_app
    response = self.full_dispatch_request()
  File "/root/anaconda3/envs/faceexpression_reco/lib/python3.6/site-packages/flask/app.py", line 1951, in full_dispatch_request
    rv = self.handle_user_exception(e)
  File "/root/anaconda3/envs/faceexpression_reco/lib/python3.6/site-packages/flask/app.py", line 1820, in handle_user_exception
    reraise(exc_type, exc_value, tb)
  File "/root/anaconda3/envs/faceexpression_reco/lib/python3.6/site-packages/flask/_compat.py", line 39, in reraise
    raise value
  File "/root/anaconda3/envs/faceexpression_reco/lib/python3.6/site-packages/flask/app.py", line 1949, in full_dispatch_request
    rv = self.dispatch_request()
  File "/root/anaconda3/envs/faceexpression_reco/lib/python3.6/site-packages/flask/app.py", line 1935, in dispatch_request
    return self.view_functions[rule.endpoint](**req.view_args)
  File "/home/iotlab/receive/receive_service.py", line 68, in uplaod_file
    result_response = js.loads(report.content)
  File "/root/anaconda3/envs/faceexpression_reco/lib/python3.6/json/__init__.py", line 354, in loads
    return _default_decoder.decode(s)
  File "/root/anaconda3/envs/faceexpression_reco/lib/python3.6/json/decoder.py", line 339, in decode
    obj, end = self.raw_decode(s, idx=_w(s, 0).end())
  File "/root/anaconda3/envs/faceexpression_reco/lib/python3.6/json/decoder.py", line 357, in raw_decode
    raise JSONDecodeError("Expecting value", s, err.value) from None
json.decoder.JSONDecodeError: Expecting value: line 1 column 1 (char 0)
[2020-03-25 03:30:04 +0800] [2081] [CRITICAL] WORKER TIMEOUT (pid:2084)
[2020-03-25 03:30:04 +0800] [2084] [INFO] Worker exiting (pid: 2084)
[2020-03-25 03:30:04 +0800] [2333] [INFO] Booting worker with pid: 2333
[2020-03-25 03:32:05 +0800] [2081] [CRITICAL] WORKER TIMEOUT (pid:2333)
[2020-03-25 03:32:05 +0800] [2333] [INFO] Worker exiting (pid: 2333)
[2020-03-25 03:32:06 +0800] [2338] [INFO] Booting worker with pid: 2338
[2020-03-25 11:04:56 +0800] [2841] [INFO] Starting gunicorn 20.0.4
[2020-03-25 11:04:56 +0800] [2841] [INFO] Listening at: http://0.0.0.0:8080 (2841)
[2020-03-25 11:04:56 +0800] [2841] [INFO] Using worker: sync
[2020-03-25 11:04:56 +0800] [2844] [INFO] Booting worker with pid: 2844
[2020-03-25 11:15:20,449] ERROR in app: Exception on /api/upload [POST]
Traceback (most recent call last):
  File "/root/anaconda3/envs/faceexpression_reco/lib/python3.6/site-packages/flask/app.py", line 2446, in wsgi_app
    response = self.full_dispatch_request()
  File "/root/anaconda3/envs/faceexpression_reco/lib/python3.6/site-packages/flask/app.py", line 1951, in full_dispatch_request
    rv = self.handle_user_exception(e)
  File "/root/anaconda3/envs/faceexpression_reco/lib/python3.6/site-packages/flask/app.py", line 1820, in handle_user_exception
    reraise(exc_type, exc_value, tb)
  File "/root/anaconda3/envs/faceexpression_reco/lib/python3.6/site-packages/flask/_compat.py", line 39, in reraise
    raise value
  File "/root/anaconda3/envs/faceexpression_reco/lib/python3.6/site-packages/flask/app.py", line 1949, in full_dispatch_request
    rv = self.dispatch_request()
  File "/root/anaconda3/envs/faceexpression_reco/lib/python3.6/site-packages/flask/app.py", line 1935, in dispatch_request
    return self.view_functions[rule.endpoint](**req.view_args)
  File "/home/iotlab/receive/receive_service.py", line 68, in uplaod_file
    result_response = js.loads(report.content)
  File "/root/anaconda3/envs/faceexpression_reco/lib/python3.6/json/__init__.py", line 354, in loads
    return _default_decoder.decode(s)
  File "/root/anaconda3/envs/faceexpression_reco/lib/python3.6/json/decoder.py", line 339, in decode
    obj, end = self.raw_decode(s, idx=_w(s, 0).end())
  File "/root/anaconda3/envs/faceexpression_reco/lib/python3.6/json/decoder.py", line 357, in raw_decode
    raise JSONDecodeError("Expecting value", s, err.value) from None
json.decoder.JSONDecodeError: Expecting value: line 1 column 1 (char 0)
[2020-03-25 11:22:22,609] ERROR in app: Exception on /api/upload [POST]
Traceback (most recent call last):
  File "/root/anaconda3/envs/faceexpression_reco/lib/python3.6/site-packages/flask/app.py", line 2446, in wsgi_app
    response = self.full_dispatch_request()
  File "/root/anaconda3/envs/faceexpression_reco/lib/python3.6/site-packages/flask/app.py", line 1951, in full_dispatch_request
    rv = self.handle_user_exception(e)
  File "/root/anaconda3/envs/faceexpression_reco/lib/python3.6/site-packages/flask/app.py", line 1820, in handle_user_exception
    reraise(exc_type, exc_value, tb)
  File "/root/anaconda3/envs/faceexpression_reco/lib/python3.6/site-packages/flask/_compat.py", line 39, in reraise
    raise value
  File "/root/anaconda3/envs/faceexpression_reco/lib/python3.6/site-packages/flask/app.py", line 1949, in full_dispatch_request
    rv = self.dispatch_request()
  File "/root/anaconda3/envs/faceexpression_reco/lib/python3.6/site-packages/flask/app.py", line 1935, in dispatch_request
    return self.view_functions[rule.endpoint](**req.view_args)
  File "/home/iotlab/receive/receive_service.py", line 68, in uplaod_file
    result_response = js.loads(report.content)
  File "/root/anaconda3/envs/faceexpression_reco/lib/python3.6/json/__init__.py", line 354, in loads
    return _default_decoder.decode(s)
  File "/root/anaconda3/envs/faceexpression_reco/lib/python3.6/json/decoder.py", line 339, in decode
    obj, end = self.raw_decode(s, idx=_w(s, 0).end())
  File "/root/anaconda3/envs/faceexpression_reco/lib/python3.6/json/decoder.py", line 357, in raw_decode
    raise JSONDecodeError("Expecting value", s, err.value) from None
json.decoder.JSONDecodeError: Expecting value: line 1 column 1 (char 0)
[2020-03-25 11:24:15,016] ERROR in app: Exception on /api/upload [POST]
Traceback (most recent call last):
  File "/root/anaconda3/envs/faceexpression_reco/lib/python3.6/site-packages/flask/app.py", line 2446, in wsgi_app
    response = self.full_dispatch_request()
  File "/root/anaconda3/envs/faceexpression_reco/lib/python3.6/site-packages/flask/app.py", line 1951, in full_dispatch_request
    rv = self.handle_user_exception(e)
  File "/root/anaconda3/envs/faceexpression_reco/lib/python3.6/site-packages/flask/app.py", line 1820, in handle_user_exception
    reraise(exc_type, exc_value, tb)
  File "/root/anaconda3/envs/faceexpression_reco/lib/python3.6/site-packages/flask/_compat.py", line 39, in reraise
    raise value
  File "/root/anaconda3/envs/faceexpression_reco/lib/python3.6/site-packages/flask/app.py", line 1949, in full_dispatch_request
    rv = self.dispatch_request()
  File "/root/anaconda3/envs/faceexpression_reco/lib/python3.6/site-packages/flask/app.py", line 1935, in dispatch_request
    return self.view_functions[rule.endpoint](**req.view_args)
  File "/home/iotlab/receive/receive_service.py", line 68, in uplaod_file
    result_response = js.loads(report.content)
  File "/root/anaconda3/envs/faceexpression_reco/lib/python3.6/json/__init__.py", line 354, in loads
    return _default_decoder.decode(s)
  File "/root/anaconda3/envs/faceexpression_reco/lib/python3.6/json/decoder.py", line 339, in decode
    obj, end = self.raw_decode(s, idx=_w(s, 0).end())
  File "/root/anaconda3/envs/faceexpression_reco/lib/python3.6/json/decoder.py", line 357, in raw_decode
    raise JSONDecodeError("Expecting value", s, err.value) from None
json.decoder.JSONDecodeError: Expecting value: line 1 column 1 (char 0)
[2020-03-25 11:24:43,056] ERROR in app: Exception on /api/upload [POST]
Traceback (most recent call last):
  File "/root/anaconda3/envs/faceexpression_reco/lib/python3.6/site-packages/flask/app.py", line 2446, in wsgi_app
    response = self.full_dispatch_request()
  File "/root/anaconda3/envs/faceexpression_reco/lib/python3.6/site-packages/flask/app.py", line 1951, in full_dispatch_request
    rv = self.handle_user_exception(e)
  File "/root/anaconda3/envs/faceexpression_reco/lib/python3.6/site-packages/flask/app.py", line 1820, in handle_user_exception
    reraise(exc_type, exc_value, tb)
  File "/root/anaconda3/envs/faceexpression_reco/lib/python3.6/site-packages/flask/_compat.py", line 39, in reraise
    raise value
  File "/root/anaconda3/envs/faceexpression_reco/lib/python3.6/site-packages/flask/app.py", line 1949, in full_dispatch_request
    rv = self.dispatch_request()
  File "/root/anaconda3/envs/faceexpression_reco/lib/python3.6/site-packages/flask/app.py", line 1935, in dispatch_request
    return self.view_functions[rule.endpoint](**req.view_args)
  File "/home/iotlab/receive/receive_service.py", line 68, in uplaod_file
    result_response = js.loads(report.content)
  File "/root/anaconda3/envs/faceexpression_reco/lib/python3.6/json/__init__.py", line 354, in loads
    return _default_decoder.decode(s)
  File "/root/anaconda3/envs/faceexpression_reco/lib/python3.6/json/decoder.py", line 339, in decode
    obj, end = self.raw_decode(s, idx=_w(s, 0).end())
  File "/root/anaconda3/envs/faceexpression_reco/lib/python3.6/json/decoder.py", line 357, in raw_decode
    raise JSONDecodeError("Expecting value", s, err.value) from None
json.decoder.JSONDecodeError: Expecting value: line 1 column 1 (char 0)
[2020-03-25 11:43:01 +0800] [3026] [INFO] Starting gunicorn 20.0.4
[2020-03-25 11:43:01 +0800] [3026] [INFO] Listening at: http://0.0.0.0:8080 (3026)
[2020-03-25 11:43:01 +0800] [3026] [INFO] Using worker: sync
[2020-03-25 11:43:01 +0800] [3029] [INFO] Booting worker with pid: 3029
[2020-03-25 11:45:57 +0800] [3138] [INFO] Starting gunicorn 20.0.4
[2020-03-25 11:45:57 +0800] [3138] [INFO] Listening at: http://0.0.0.0:8080 (3138)
[2020-03-25 11:45:57 +0800] [3138] [INFO] Using worker: sync
[2020-03-25 11:45:57 +0800] [3141] [INFO] Booting worker with pid: 3141
[2020-03-25 11:46:23,507] ERROR in app: Exception on /api/upload [POST]
Traceback (most recent call last):
  File "/root/anaconda3/envs/faceexpression_reco/lib/python3.6/site-packages/flask/app.py", line 2446, in wsgi_app
    response = self.full_dispatch_request()
  File "/root/anaconda3/envs/faceexpression_reco/lib/python3.6/site-packages/flask/app.py", line 1951, in full_dispatch_request
    rv = self.handle_user_exception(e)
  File "/root/anaconda3/envs/faceexpression_reco/lib/python3.6/site-packages/flask/app.py", line 1820, in handle_user_exception
    reraise(exc_type, exc_value, tb)
  File "/root/anaconda3/envs/faceexpression_reco/lib/python3.6/site-packages/flask/_compat.py", line 39, in reraise
    raise value
  File "/root/anaconda3/envs/faceexpression_reco/lib/python3.6/site-packages/flask/app.py", line 1949, in full_dispatch_request
    rv = self.dispatch_request()
  File "/root/anaconda3/envs/faceexpression_reco/lib/python3.6/site-packages/flask/app.py", line 1935, in dispatch_request
    return self.view_functions[rule.endpoint](**req.view_args)
  File "/home/iotlab/receive/receive_service.py", line 68, in uplaod_file
    result_response = js.loads(report.content)
  File "/root/anaconda3/envs/faceexpression_reco/lib/python3.6/json/__init__.py", line 354, in loads
    return _default_decoder.decode(s)
  File "/root/anaconda3/envs/faceexpression_reco/lib/python3.6/json/decoder.py", line 339, in decode
    obj, end = self.raw_decode(s, idx=_w(s, 0).end())
  File "/root/anaconda3/envs/faceexpression_reco/lib/python3.6/json/decoder.py", line 357, in raw_decode
    raise JSONDecodeError("Expecting value", s, err.value) from None
json.decoder.JSONDecodeError: Expecting value: line 1 column 1 (char 0)
[2020-03-25 14:03:36 +0800] [3138] [CRITICAL] WORKER TIMEOUT (pid:3141)
[2020-03-25 14:03:36 +0800] [3141] [INFO] Worker exiting (pid: 3141)
[2020-03-25 14:03:36 +0800] [3238] [INFO] Booting worker with pid: 3238
[2020-03-25 15:26:03 +0800] [3424] [INFO] Starting gunicorn 20.0.4
[2020-03-25 15:26:03 +0800] [3424] [INFO] Listening at: http://0.0.0.0:8080 (3424)
[2020-03-25 15:26:03 +0800] [3424] [INFO] Using worker: sync
[2020-03-25 15:26:03 +0800] [3427] [INFO] Booting worker with pid: 3427
[2020-03-25 15:52:30 +0800] [3616] [INFO] Starting gunicorn 20.0.4
[2020-03-25 15:52:30 +0800] [3616] [INFO] Listening at: http://0.0.0.0:8080 (3616)
[2020-03-25 15:52:30 +0800] [3616] [INFO] Using worker: sync
[2020-03-25 15:52:30 +0800] [3619] [INFO] Booting worker with pid: 3619
[2020-03-25 16:18:02,989] ERROR in app: Exception on /api/upload [POST]
Traceback (most recent call last):
  File "/root/anaconda3/envs/faceexpression_reco/lib/python3.6/site-packages/flask/app.py", line 2446, in wsgi_app
    response = self.full_dispatch_request()
  File "/root/anaconda3/envs/faceexpression_reco/lib/python3.6/site-packages/flask/app.py", line 1951, in full_dispatch_request
    rv = self.handle_user_exception(e)
  File "/root/anaconda3/envs/faceexpression_reco/lib/python3.6/site-packages/flask/app.py", line 1820, in handle_user_exception
    reraise(exc_type, exc_value, tb)
  File "/root/anaconda3/envs/faceexpression_reco/lib/python3.6/site-packages/flask/_compat.py", line 39, in reraise
    raise value
  File "/root/anaconda3/envs/faceexpression_reco/lib/python3.6/site-packages/flask/app.py", line 1949, in full_dispatch_request
    rv = self.dispatch_request()
  File "/root/anaconda3/envs/faceexpression_reco/lib/python3.6/site-packages/flask/app.py", line 1935, in dispatch_request
    return self.view_functions[rule.endpoint](**req.view_args)
  File "/home/iotlab/receive/receive_service.py", line 99, in uplaod_file
    return result
UnboundLocalError: local variable 'result' referenced before assignment
[2020-03-25 16:18:33,037] ERROR in app: Exception on /api/upload [POST]
Traceback (most recent call last):
  File "/root/anaconda3/envs/faceexpression_reco/lib/python3.6/site-packages/flask/app.py", line 2446, in wsgi_app
    response = self.full_dispatch_request()
  File "/root/anaconda3/envs/faceexpression_reco/lib/python3.6/site-packages/flask/app.py", line 1951, in full_dispatch_request
    rv = self.handle_user_exception(e)
  File "/root/anaconda3/envs/faceexpression_reco/lib/python3.6/site-packages/flask/app.py", line 1820, in handle_user_exception
    reraise(exc_type, exc_value, tb)
  File "/root/anaconda3/envs/faceexpression_reco/lib/python3.6/site-packages/flask/_compat.py", line 39, in reraise
    raise value
  File "/root/anaconda3/envs/faceexpression_reco/lib/python3.6/site-packages/flask/app.py", line 1949, in full_dispatch_request
    rv = self.dispatch_request()
  File "/root/anaconda3/envs/faceexpression_reco/lib/python3.6/site-packages/flask/app.py", line 1935, in dispatch_request
    return self.view_functions[rule.endpoint](**req.view_args)
  File "/home/iotlab/receive/receive_service.py", line 99, in uplaod_file
    return result
UnboundLocalError: local variable 'result' referenced before assignment
[2020-03-25 16:38:11,291] ERROR in app: Exception on /api/upload [POST]
Traceback (most recent call last):
  File "/root/anaconda3/envs/faceexpression_reco/lib/python3.6/site-packages/flask/app.py", line 2446, in wsgi_app
    response = self.full_dispatch_request()
  File "/root/anaconda3/envs/faceexpression_reco/lib/python3.6/site-packages/flask/app.py", line 1951, in full_dispatch_request
    rv = self.handle_user_exception(e)
  File "/root/anaconda3/envs/faceexpression_reco/lib/python3.6/site-packages/flask/app.py", line 1820, in handle_user_exception
    reraise(exc_type, exc_value, tb)
  File "/root/anaconda3/envs/faceexpression_reco/lib/python3.6/site-packages/flask/_compat.py", line 39, in reraise
    raise value
  File "/root/anaconda3/envs/faceexpression_reco/lib/python3.6/site-packages/flask/app.py", line 1949, in full_dispatch_request
    rv = self.dispatch_request()
  File "/root/anaconda3/envs/faceexpression_reco/lib/python3.6/site-packages/flask/app.py", line 1935, in dispatch_request
    return self.view_functions[rule.endpoint](**req.view_args)
  File "/home/iotlab/receive/receive_service.py", line 99, in uplaod_file
    return result
UnboundLocalError: local variable 'result' referenced before assignment
[2020-03-25 17:55:05 +0800] [3619] [ERROR] Socket error processing request.
Traceback (most recent call last):
  File "/root/anaconda3/envs/faceexpression_reco/lib/python3.6/site-packages/gunicorn/workers/sync.py", line 133, in handle
    req = next(parser)
  File "/root/anaconda3/envs/faceexpression_reco/lib/python3.6/site-packages/gunicorn/http/parser.py", line 41, in __next__
    self.mesg = self.mesg_class(self.cfg, self.unreader, self.req_count)
  File "/root/anaconda3/envs/faceexpression_reco/lib/python3.6/site-packages/gunicorn/http/message.py", line 186, in __init__
    super().__init__(cfg, unreader)
  File "/root/anaconda3/envs/faceexpression_reco/lib/python3.6/site-packages/gunicorn/http/message.py", line 53, in __init__
    unused = self.parse(self.unreader)
  File "/root/anaconda3/envs/faceexpression_reco/lib/python3.6/site-packages/gunicorn/http/message.py", line 235, in parse
    self.headers = self.parse_headers(data[:idx])
  File "/root/anaconda3/envs/faceexpression_reco/lib/python3.6/site-packages/gunicorn/http/message.py", line 73, in parse_headers
    remote_addr = self.unreader.sock.getpeername()
OSError: [Errno 107] Transport endpoint is not connected
[2020-03-25 17:59:08 +0800] [3616] [CRITICAL] WORKER TIMEOUT (pid:3619)
[2020-03-25 17:59:08 +0800] [3619] [INFO] Worker exiting (pid: 3619)
[2020-03-25 17:59:09 +0800] [3785] [INFO] Booting worker with pid: 3785
[2020-03-25 18:16:35 +0800] [3785] [ERROR] Socket error processing request.
Traceback (most recent call last):
  File "/root/anaconda3/envs/faceexpression_reco/lib/python3.6/site-packages/gunicorn/workers/sync.py", line 133, in handle
    req = next(parser)
  File "/root/anaconda3/envs/faceexpression_reco/lib/python3.6/site-packages/gunicorn/http/parser.py", line 41, in __next__
    self.mesg = self.mesg_class(self.cfg, self.unreader, self.req_count)
  File "/root/anaconda3/envs/faceexpression_reco/lib/python3.6/site-packages/gunicorn/http/message.py", line 186, in __init__
    super().__init__(cfg, unreader)
  File "/root/anaconda3/envs/faceexpression_reco/lib/python3.6/site-packages/gunicorn/http/message.py", line 53, in __init__
    unused = self.parse(self.unreader)
  File "/root/anaconda3/envs/faceexpression_reco/lib/python3.6/site-packages/gunicorn/http/message.py", line 235, in parse
    self.headers = self.parse_headers(data[:idx])
  File "/root/anaconda3/envs/faceexpression_reco/lib/python3.6/site-packages/gunicorn/http/message.py", line 73, in parse_headers
    remote_addr = self.unreader.sock.getpeername()
OSError: [Errno 107] Transport endpoint is not connected
[2020-03-25 18:16:35 +0800] [3785] [ERROR] Socket error processing request.
Traceback (most recent call last):
  File "/root/anaconda3/envs/faceexpression_reco/lib/python3.6/site-packages/gunicorn/workers/sync.py", line 133, in handle
    req = next(parser)
  File "/root/anaconda3/envs/faceexpression_reco/lib/python3.6/site-packages/gunicorn/http/parser.py", line 41, in __next__
    self.mesg = self.mesg_class(self.cfg, self.unreader, self.req_count)
  File "/root/anaconda3/envs/faceexpression_reco/lib/python3.6/site-packages/gunicorn/http/message.py", line 186, in __init__
    super().__init__(cfg, unreader)
  File "/root/anaconda3/envs/faceexpression_reco/lib/python3.6/site-packages/gunicorn/http/message.py", line 53, in __init__
    unused = self.parse(self.unreader)
  File "/root/anaconda3/envs/faceexpression_reco/lib/python3.6/site-packages/gunicorn/http/message.py", line 235, in parse
    self.headers = self.parse_headers(data[:idx])
  File "/root/anaconda3/envs/faceexpression_reco/lib/python3.6/site-packages/gunicorn/http/message.py", line 73, in parse_headers
    remote_addr = self.unreader.sock.getpeername()
OSError: [Errno 107] Transport endpoint is not connected
[2020-03-25 23:15:39 +0800] [3616] [CRITICAL] WORKER TIMEOUT (pid:3785)
[2020-03-25 23:15:39 +0800] [3785] [INFO] Worker exiting (pid: 3785)
[2020-03-25 23:15:39 +0800] [4027] [INFO] Booting worker with pid: 4027
[2020-03-25 23:15:40 +0800] [4027] [ERROR] Socket error processing request.
Traceback (most recent call last):
  File "/root/anaconda3/envs/faceexpression_reco/lib/python3.6/site-packages/gunicorn/workers/sync.py", line 133, in handle
    req = next(parser)
  File "/root/anaconda3/envs/faceexpression_reco/lib/python3.6/site-packages/gunicorn/http/parser.py", line 41, in __next__
    self.mesg = self.mesg_class(self.cfg, self.unreader, self.req_count)
  File "/root/anaconda3/envs/faceexpression_reco/lib/python3.6/site-packages/gunicorn/http/message.py", line 186, in __init__
    super().__init__(cfg, unreader)
  File "/root/anaconda3/envs/faceexpression_reco/lib/python3.6/site-packages/gunicorn/http/message.py", line 53, in __init__
    unused = self.parse(self.unreader)
  File "/root/anaconda3/envs/faceexpression_reco/lib/python3.6/site-packages/gunicorn/http/message.py", line 235, in parse
    self.headers = self.parse_headers(data[:idx])
  File "/root/anaconda3/envs/faceexpression_reco/lib/python3.6/site-packages/gunicorn/http/message.py", line 73, in parse_headers
    remote_addr = self.unreader.sock.getpeername()
OSError: [Errno 107] Transport endpoint is not connected
[2020-03-26 08:57:05 +0800] [4027] [ERROR] Socket error processing request.
Traceback (most recent call last):
  File "/root/anaconda3/envs/faceexpression_reco/lib/python3.6/site-packages/gunicorn/workers/sync.py", line 133, in handle
    req = next(parser)
  File "/root/anaconda3/envs/faceexpression_reco/lib/python3.6/site-packages/gunicorn/http/parser.py", line 41, in __next__
    self.mesg = self.mesg_class(self.cfg, self.unreader, self.req_count)
  File "/root/anaconda3/envs/faceexpression_reco/lib/python3.6/site-packages/gunicorn/http/message.py", line 186, in __init__
    super().__init__(cfg, unreader)
  File "/root/anaconda3/envs/faceexpression_reco/lib/python3.6/site-packages/gunicorn/http/message.py", line 53, in __init__
    unused = self.parse(self.unreader)
  File "/root/anaconda3/envs/faceexpression_reco/lib/python3.6/site-packages/gunicorn/http/message.py", line 235, in parse
    self.headers = self.parse_headers(data[:idx])
  File "/root/anaconda3/envs/faceexpression_reco/lib/python3.6/site-packages/gunicorn/http/message.py", line 73, in parse_headers
    remote_addr = self.unreader.sock.getpeername()
OSError: [Errno 107] Transport endpoint is not connected
[2020-03-26 14:04:47 +0800] [3616] [CRITICAL] WORKER TIMEOUT (pid:4027)
[2020-03-26 14:04:47 +0800] [4027] [INFO] Worker exiting (pid: 4027)
[2020-03-26 14:04:47 +0800] [4642] [INFO] Booting worker with pid: 4642
[2020-03-27 14:05:58 +0800] [3616] [CRITICAL] WORKER TIMEOUT (pid:4642)
[2020-03-27 14:05:58 +0800] [4642] [INFO] Worker exiting (pid: 4642)
[2020-03-27 14:05:58 +0800] [5526] [INFO] Booting worker with pid: 5526
[2020-03-27 22:05:47 +0800] [3616] [CRITICAL] WORKER TIMEOUT (pid:5526)
[2020-03-27 22:05:47 +0800] [5526] [INFO] Worker exiting (pid: 5526)
[2020-03-27 22:05:47 +0800] [5792] [INFO] Booting worker with pid: 5792
[2020-03-28 11:18:52 +0800] [3616] [CRITICAL] WORKER TIMEOUT (pid:5792)
[2020-03-28 11:18:52 +0800] [5792] [INFO] Worker exiting (pid: 5792)
[2020-03-28 11:18:52 +0800] [6339] [INFO] Booting worker with pid: 6339
[2020-03-29 13:49:59 +0800] [3616] [CRITICAL] WORKER TIMEOUT (pid:6339)
[2020-03-29 13:49:59 +0800] [6339] [INFO] Worker exiting (pid: 6339)
[2020-03-29 13:49:59 +0800] [7297] [INFO] Booting worker with pid: 7297
[2020-03-30 08:23:27 +0800] [3616] [CRITICAL] WORKER TIMEOUT (pid:7297)
[2020-03-30 08:23:27 +0800] [7297] [INFO] Worker exiting (pid: 7297)
[2020-03-30 08:23:27 +0800] [8016] [INFO] Booting worker with pid: 8016
[2020-03-30 18:34:02 +0800] [3616] [CRITICAL] WORKER TIMEOUT (pid:8016)
[2020-03-30 18:34:02 +0800] [8016] [INFO] Worker exiting (pid: 8016)
[2020-03-30 18:34:02 +0800] [8371] [INFO] Booting worker with pid: 8371
[2020-03-31 05:43:15 +0800] [3616] [CRITICAL] WORKER TIMEOUT (pid:8371)
[2020-03-31 05:43:15 +0800] [8371] [INFO] Worker exiting (pid: 8371)
[2020-03-31 05:43:15 +0800] [8751] [INFO] Booting worker with pid: 8751
[2020-03-31 05:45:41 +0800] [3616] [CRITICAL] WORKER TIMEOUT (pid:8751)
[2020-03-31 05:45:41 +0800] [8751] [INFO] Worker exiting (pid: 8751)
[2020-03-31 05:45:41 +0800] [8759] [INFO] Booting worker with pid: 8759
[2020-03-31 05:52:29 +0800] [3616] [CRITICAL] WORKER TIMEOUT (pid:8759)
[2020-03-31 05:52:29 +0800] [8759] [INFO] Worker exiting (pid: 8759)
[2020-03-31 05:52:29 +0800] [8764] [INFO] Booting worker with pid: 8764
[2020-03-31 05:54:30 +0800] [3616] [CRITICAL] WORKER TIMEOUT (pid:8764)
[2020-03-31 05:54:30 +0800] [8764] [INFO] Worker exiting (pid: 8764)
[2020-03-31 05:54:30 +0800] [8769] [INFO] Booting worker with pid: 8769
[2020-03-31 05:56:31 +0800] [3616] [CRITICAL] WORKER TIMEOUT (pid:8769)
[2020-03-31 05:56:31 +0800] [8769] [INFO] Worker exiting (pid: 8769)
[2020-03-31 05:56:31 +0800] [8777] [INFO] Booting worker with pid: 8777
[2020-03-31 06:10:58 +0800] [3616] [CRITICAL] WORKER TIMEOUT (pid:8777)
[2020-03-31 06:10:58 +0800] [8777] [INFO] Worker exiting (pid: 8777)
[2020-03-31 06:10:58 +0800] [8788] [INFO] Booting worker with pid: 8788
[2020-03-31 14:58:48 +0800] [3616] [CRITICAL] WORKER TIMEOUT (pid:8788)
[2020-03-31 14:58:48 +0800] [8788] [INFO] Worker exiting (pid: 8788)
[2020-03-31 14:58:48 +0800] [9163] [INFO] Booting worker with pid: 9163
[2020-03-31 14:58:52 +0800] [9163] [ERROR] Socket error processing request.
Traceback (most recent call last):
  File "/root/anaconda3/envs/faceexpression_reco/lib/python3.6/site-packages/gunicorn/workers/sync.py", line 133, in handle
    req = next(parser)
  File "/root/anaconda3/envs/faceexpression_reco/lib/python3.6/site-packages/gunicorn/http/parser.py", line 41, in __next__
    self.mesg = self.mesg_class(self.cfg, self.unreader, self.req_count)
  File "/root/anaconda3/envs/faceexpression_reco/lib/python3.6/site-packages/gunicorn/http/message.py", line 186, in __init__
    super().__init__(cfg, unreader)
  File "/root/anaconda3/envs/faceexpression_reco/lib/python3.6/site-packages/gunicorn/http/message.py", line 53, in __init__
    unused = self.parse(self.unreader)
  File "/root/anaconda3/envs/faceexpression_reco/lib/python3.6/site-packages/gunicorn/http/message.py", line 235, in parse
    self.headers = self.parse_headers(data[:idx])
  File "/root/anaconda3/envs/faceexpression_reco/lib/python3.6/site-packages/gunicorn/http/message.py", line 73, in parse_headers
    remote_addr = self.unreader.sock.getpeername()
OSError: [Errno 107] Transport endpoint is not connected
[2020-03-31 14:58:52 +0800] [9163] [ERROR] Socket error processing request.
Traceback (most recent call last):
  File "/root/anaconda3/envs/faceexpression_reco/lib/python3.6/site-packages/gunicorn/workers/sync.py", line 133, in handle
    req = next(parser)
  File "/root/anaconda3/envs/faceexpression_reco/lib/python3.6/site-packages/gunicorn/http/parser.py", line 41, in __next__
    self.mesg = self.mesg_class(self.cfg, self.unreader, self.req_count)
  File "/root/anaconda3/envs/faceexpression_reco/lib/python3.6/site-packages/gunicorn/http/message.py", line 186, in __init__
    super().__init__(cfg, unreader)
  File "/root/anaconda3/envs/faceexpression_reco/lib/python3.6/site-packages/gunicorn/http/message.py", line 53, in __init__
    unused = self.parse(self.unreader)
  File "/root/anaconda3/envs/faceexpression_reco/lib/python3.6/site-packages/gunicorn/http/message.py", line 235, in parse
    self.headers = self.parse_headers(data[:idx])
  File "/root/anaconda3/envs/faceexpression_reco/lib/python3.6/site-packages/gunicorn/http/message.py", line 73, in parse_headers
    remote_addr = self.unreader.sock.getpeername()
OSError: [Errno 107] Transport endpoint is not connected
[2020-03-31 15:02:46 +0800] [9163] [ERROR] Socket error processing request.
Traceback (most recent call last):
  File "/root/anaconda3/envs/faceexpression_reco/lib/python3.6/site-packages/gunicorn/workers/sync.py", line 133, in handle
    req = next(parser)
  File "/root/anaconda3/envs/faceexpression_reco/lib/python3.6/site-packages/gunicorn/http/parser.py", line 41, in __next__
    self.mesg = self.mesg_class(self.cfg, self.unreader, self.req_count)
  File "/root/anaconda3/envs/faceexpression_reco/lib/python3.6/site-packages/gunicorn/http/message.py", line 186, in __init__
    super().__init__(cfg, unreader)
  File "/root/anaconda3/envs/faceexpression_reco/lib/python3.6/site-packages/gunicorn/http/message.py", line 53, in __init__
    unused = self.parse(self.unreader)
  File "/root/anaconda3/envs/faceexpression_reco/lib/python3.6/site-packages/gunicorn/http/message.py", line 235, in parse
    self.headers = self.parse_headers(data[:idx])
  File "/root/anaconda3/envs/faceexpression_reco/lib/python3.6/site-packages/gunicorn/http/message.py", line 73, in parse_headers
    remote_addr = self.unreader.sock.getpeername()
OSError: [Errno 107] Transport endpoint is not connected
[2020-03-31 15:02:46 +0800] [9163] [ERROR] Socket error processing request.
Traceback (most recent call last):
  File "/root/anaconda3/envs/faceexpression_reco/lib/python3.6/site-packages/gunicorn/workers/sync.py", line 133, in handle
    req = next(parser)
  File "/root/anaconda3/envs/faceexpression_reco/lib/python3.6/site-packages/gunicorn/http/parser.py", line 41, in __next__
    self.mesg = self.mesg_class(self.cfg, self.unreader, self.req_count)
  File "/root/anaconda3/envs/faceexpression_reco/lib/python3.6/site-packages/gunicorn/http/message.py", line 186, in __init__
    super().__init__(cfg, unreader)
  File "/root/anaconda3/envs/faceexpression_reco/lib/python3.6/site-packages/gunicorn/http/message.py", line 53, in __init__
    unused = self.parse(self.unreader)
  File "/root/anaconda3/envs/faceexpression_reco/lib/python3.6/site-packages/gunicorn/http/message.py", line 235, in parse
    self.headers = self.parse_headers(data[:idx])
  File "/root/anaconda3/envs/faceexpression_reco/lib/python3.6/site-packages/gunicorn/http/message.py", line 73, in parse_headers
    remote_addr = self.unreader.sock.getpeername()
OSError: [Errno 107] Transport endpoint is not connected
[2020-04-01 14:04:06 +0800] [3616] [CRITICAL] WORKER TIMEOUT (pid:9163)
[2020-04-01 14:04:06 +0800] [9163] [INFO] Worker exiting (pid: 9163)
[2020-04-01 14:04:06 +0800] [10035] [INFO] Booting worker with pid: 10035
[2020-04-02 10:08:19 +0800] [3616] [CRITICAL] WORKER TIMEOUT (pid:10035)
[2020-04-02 10:08:19 +0800] [10035] [INFO] Worker exiting (pid: 10035)
[2020-04-02 10:08:19 +0800] [10820] [INFO] Booting worker with pid: 10820
[2020-04-02 23:16:22 +0800] [3616] [CRITICAL] WORKER TIMEOUT (pid:10820)
[2020-04-02 23:16:22 +0800] [10820] [INFO] Worker exiting (pid: 10820)
[2020-04-02 23:16:22 +0800] [11246] [INFO] Booting worker with pid: 11246
[2020-04-03 14:03:24 +0800] [11246] [ERROR] Socket error processing request.
Traceback (most recent call last):
  File "/root/anaconda3/envs/faceexpression_reco/lib/python3.6/site-packages/gunicorn/workers/sync.py", line 133, in handle
    req = next(parser)
  File "/root/anaconda3/envs/faceexpression_reco/lib/python3.6/site-packages/gunicorn/http/parser.py", line 41, in __next__
    self.mesg = self.mesg_class(self.cfg, self.unreader, self.req_count)
  File "/root/anaconda3/envs/faceexpression_reco/lib/python3.6/site-packages/gunicorn/http/message.py", line 186, in __init__
    super().__init__(cfg, unreader)
  File "/root/anaconda3/envs/faceexpression_reco/lib/python3.6/site-packages/gunicorn/http/message.py", line 53, in __init__
    unused = self.parse(self.unreader)
  File "/root/anaconda3/envs/faceexpression_reco/lib/python3.6/site-packages/gunicorn/http/message.py", line 235, in parse
    self.headers = self.parse_headers(data[:idx])
  File "/root/anaconda3/envs/faceexpression_reco/lib/python3.6/site-packages/gunicorn/http/message.py", line 73, in parse_headers
    remote_addr = self.unreader.sock.getpeername()
OSError: [Errno 107] Transport endpoint is not connected
[2020-04-03 23:11:08 +0800] [3616] [CRITICAL] WORKER TIMEOUT (pid:11246)
[2020-04-03 23:11:08 +0800] [11246] [INFO] Worker exiting (pid: 11246)
[2020-04-03 23:11:08 +0800] [12138] [INFO] Booting worker with pid: 12138
[2020-04-05 02:03:27 +0800] [12138] [ERROR] Socket error processing request.
Traceback (most recent call last):
  File "/root/anaconda3/envs/faceexpression_reco/lib/python3.6/site-packages/gunicorn/workers/sync.py", line 133, in handle
    req = next(parser)
  File "/root/anaconda3/envs/faceexpression_reco/lib/python3.6/site-packages/gunicorn/http/parser.py", line 41, in __next__
    self.mesg = self.mesg_class(self.cfg, self.unreader, self.req_count)
  File "/root/anaconda3/envs/faceexpression_reco/lib/python3.6/site-packages/gunicorn/http/message.py", line 186, in __init__
    super().__init__(cfg, unreader)
  File "/root/anaconda3/envs/faceexpression_reco/lib/python3.6/site-packages/gunicorn/http/message.py", line 53, in __init__
    unused = self.parse(self.unreader)
  File "/root/anaconda3/envs/faceexpression_reco/lib/python3.6/site-packages/gunicorn/http/message.py", line 235, in parse
    self.headers = self.parse_headers(data[:idx])
  File "/root/anaconda3/envs/faceexpression_reco/lib/python3.6/site-packages/gunicorn/http/message.py", line 73, in parse_headers
    remote_addr = self.unreader.sock.getpeername()
OSError: [Errno 107] Transport endpoint is not connected
[2020-04-05 18:08:35 +0800] [3616] [CRITICAL] WORKER TIMEOUT (pid:12138)
[2020-04-05 18:08:35 +0800] [12138] [INFO] Worker exiting (pid: 12138)
[2020-04-05 18:08:35 +0800] [13905] [INFO] Booting worker with pid: 13905
