2020-03-24 16:26:59 [11250] [INFO] Starting gunicorn 17.5
2020-03-24 16:26:59 [11250] [INFO] Listening at: http://127.0.0.1:4014 (11250)
2020-03-24 16:26:59 [11250] [INFO] Using worker: sync
2020-03-24 16:26:59 [11255] [INFO] Booting worker with pid: 11255
2020-03-24 16:26:59 [11255] [ERROR] Exception in worker process:
Traceback (most recent call last):
  File "/usr/lib/python2.7/dist-packages/gunicorn/arbiter.py", line 473, in spawn_worker
    worker.init_process()
  File "/usr/lib/python2.7/dist-packages/gunicorn/workers/base.py", line 100, in init_process
    self.wsgi = self.app.wsgi()
  File "/usr/lib/python2.7/dist-packages/gunicorn/app/base.py", line 115, in wsgi
    self.callable = self.load()
  File "/usr/lib/python2.7/dist-packages/gunicorn/app/wsgiapp.py", line 33, in load
    return util.import_app(self.app_uri)
  File "/usr/lib/python2.7/dist-packages/gunicorn/util.py", line 362, in import_app
    __import__(module)
  File "/home/iotlab/Facialrec/server_facial.py", line 16, in <module>
    from flask import Flask,request,jsonify
ImportError: No module named flask
Traceback (most recent call last):
  File "/usr/lib/python2.7/dist-packages/gunicorn/arbiter.py", line 473, in spawn_worker
    worker.init_process()
  File "/usr/lib/python2.7/dist-packages/gunicorn/workers/base.py", line 100, in init_process
    self.wsgi = self.app.wsgi()
  File "/usr/lib/python2.7/dist-packages/gunicorn/app/base.py", line 115, in wsgi
    self.callable = self.load()
  File "/usr/lib/python2.7/dist-packages/gunicorn/app/wsgiapp.py", line 33, in load
    return util.import_app(self.app_uri)
  File "/usr/lib/python2.7/dist-packages/gunicorn/util.py", line 362, in import_app
    __import__(module)
  File "/home/iotlab/Facialrec/server_facial.py", line 16, in <module>
    from flask import Flask,request,jsonify
ImportError: No module named flask
2020-03-24 16:26:59 [11255] [INFO] Worker exiting (pid: 11255)
2020-03-24 16:26:59 [11250] [INFO] Shutting down: Master
2020-03-24 16:26:59 [11250] [INFO] Reason: Worker failed to boot.
2020-03-24 16:32:41 [11293] [INFO] Starting gunicorn 17.5
2020-03-24 16:32:41 [11293] [INFO] Listening at: http://127.0.0.1:4014 (11293)
2020-03-24 16:32:41 [11293] [INFO] Using worker: sync
2020-03-24 16:32:41 [11298] [INFO] Booting worker with pid: 11298
2020-03-24 16:32:41 [11298] [ERROR] Exception in worker process:
Traceback (most recent call last):
  File "/usr/lib/python2.7/dist-packages/gunicorn/arbiter.py", line 473, in spawn_worker
    worker.init_process()
  File "/usr/lib/python2.7/dist-packages/gunicorn/workers/base.py", line 100, in init_process
    self.wsgi = self.app.wsgi()
  File "/usr/lib/python2.7/dist-packages/gunicorn/app/base.py", line 115, in wsgi
    self.callable = self.load()
  File "/usr/lib/python2.7/dist-packages/gunicorn/app/wsgiapp.py", line 33, in load
    return util.import_app(self.app_uri)
  File "/usr/lib/python2.7/dist-packages/gunicorn/util.py", line 362, in import_app
    __import__(module)
  File "/home/iotlab/Facialrec/server_facial.py", line 16, in <module>
    from flask import Flask,request,jsonify
ImportError: No module named flask
Traceback (most recent call last):
  File "/usr/lib/python2.7/dist-packages/gunicorn/arbiter.py", line 473, in spawn_worker
    worker.init_process()
  File "/usr/lib/python2.7/dist-packages/gunicorn/workers/base.py", line 100, in init_process
    self.wsgi = self.app.wsgi()
  File "/usr/lib/python2.7/dist-packages/gunicorn/app/base.py", line 115, in wsgi
    self.callable = self.load()
  File "/usr/lib/python2.7/dist-packages/gunicorn/app/wsgiapp.py", line 33, in load
    return util.import_app(self.app_uri)
  File "/usr/lib/python2.7/dist-packages/gunicorn/util.py", line 362, in import_app
    __import__(module)
  File "/home/iotlab/Facialrec/server_facial.py", line 16, in <module>
    from flask import Flask,request,jsonify
ImportError: No module named flask
2020-03-24 16:32:41 [11298] [INFO] Worker exiting (pid: 11298)
2020-03-24 16:32:41 [11293] [INFO] Shutting down: Master
2020-03-24 16:32:41 [11293] [INFO] Reason: Worker failed to boot.
[2020-03-24 16:48:16 +0800] [13513] [INFO] Starting gunicorn 20.0.4
[2020-03-24 16:48:16 +0800] [13513] [INFO] Listening at: http://127.0.0.1:4014 (13513)
[2020-03-24 16:48:16 +0800] [13513] [INFO] Using worker: sync
[2020-03-24 16:48:16 +0800] [13516] [INFO] Booting worker with pid: 13516
[2020-03-24 16:48:17 +0800] [13516] [ERROR] Exception in worker process
Traceback (most recent call last):
  File "/root/anaconda3/envs/faceexpression_reco/lib/python3.6/site-packages/gunicorn/arbiter.py", line 583, in spawn_worker
    worker.init_process()
  File "/root/anaconda3/envs/faceexpression_reco/lib/python3.6/site-packages/gunicorn/workers/base.py", line 119, in init_process
    self.load_wsgi()
  File "/root/anaconda3/envs/faceexpression_reco/lib/python3.6/site-packages/gunicorn/workers/base.py", line 144, in load_wsgi
    self.wsgi = self.app.wsgi()
  File "/root/anaconda3/envs/faceexpression_reco/lib/python3.6/site-packages/gunicorn/app/base.py", line 67, in wsgi
    self.callable = self.load()
  File "/root/anaconda3/envs/faceexpression_reco/lib/python3.6/site-packages/gunicorn/app/wsgiapp.py", line 49, in load
    return self.load_wsgiapp()
  File "/root/anaconda3/envs/faceexpression_reco/lib/python3.6/site-packages/gunicorn/app/wsgiapp.py", line 39, in load_wsgiapp
    return util.import_app(self.app_uri)
  File "/root/anaconda3/envs/faceexpression_reco/lib/python3.6/site-packages/gunicorn/util.py", line 358, in import_app
    mod = importlib.import_module(module)
  File "/root/anaconda3/envs/faceexpression_reco/lib/python3.6/importlib/__init__.py", line 126, in import_module
    return _bootstrap._gcd_import(name[level:], package, level)
  File "<frozen importlib._bootstrap>", line 994, in _gcd_import
  File "<frozen importlib._bootstrap>", line 971, in _find_and_load
  File "<frozen importlib._bootstrap>", line 955, in _find_and_load_unlocked
  File "<frozen importlib._bootstrap>", line 665, in _load_unlocked
  File "<frozen importlib._bootstrap_external>", line 678, in exec_module
  File "<frozen importlib._bootstrap>", line 219, in _call_with_frames_removed
  File "/home/iotlab/Facialrec/server_facial.py", line 18, in <module>
    import cv2
  File "/root/anaconda3/envs/faceexpression_reco/lib/python3.6/site-packages/cv2/__init__.py", line 3, in <module>
    from .cv2 import *
ImportError: libXrender.so.1: cannot open shared object file: No such file or directory
[2020-03-24 16:48:17 +0800] [13516] [INFO] Worker exiting (pid: 13516)
[2020-03-24 16:48:17 +0800] [13513] [INFO] Shutting down: Master
[2020-03-24 16:48:17 +0800] [13513] [INFO] Reason: Worker failed to boot.
[2020-03-24 17:06:29 +0800] [14911] [INFO] Starting gunicorn 20.0.4
[2020-03-24 17:06:29 +0800] [14911] [ERROR] Connection in use: ('127.0.0.1', 4014)
[2020-03-24 17:06:29 +0800] [14911] [ERROR] Retrying in 1 second.
[2020-03-24 17:06:30 +0800] [14911] [ERROR] Connection in use: ('127.0.0.1', 4014)
[2020-03-24 17:06:30 +0800] [14911] [ERROR] Retrying in 1 second.
[2020-03-24 17:06:31 +0800] [14911] [ERROR] Connection in use: ('127.0.0.1', 4014)
[2020-03-24 17:06:31 +0800] [14911] [ERROR] Retrying in 1 second.
[2020-03-24 17:06:32 +0800] [14911] [ERROR] Connection in use: ('127.0.0.1', 4014)
[2020-03-24 17:06:32 +0800] [14911] [ERROR] Retrying in 1 second.
[2020-03-24 17:06:33 +0800] [14911] [ERROR] Connection in use: ('127.0.0.1', 4014)
[2020-03-24 17:06:33 +0800] [14911] [ERROR] Retrying in 1 second.
[2020-03-24 17:06:34 +0800] [14911] [ERROR] Can't connect to ('127.0.0.1', 4014)
[2020-03-24 17:08:58 +0800] [14934] [INFO] Starting gunicorn 20.0.4
[2020-03-24 17:08:58 +0800] [14934] [INFO] Listening at: http://127.0.0.1:4014 (14934)
[2020-03-24 17:08:58 +0800] [14934] [INFO] Using worker: sync
[2020-03-24 17:08:58 +0800] [14937] [INFO] Booting worker with pid: 14937
[2020-03-24 21:06:27 +0800] [1594] [INFO] Starting gunicorn 20.0.4
[2020-03-24 21:06:27 +0800] [1594] [INFO] Listening at: http://127.0.0.1:4014 (1594)
[2020-03-24 21:06:27 +0800] [1594] [INFO] Using worker: sync
[2020-03-24 21:06:27 +0800] [1597] [INFO] Booting worker with pid: 1597
[2020-03-24 21:11:41 +0800] [1667] [INFO] Starting gunicorn 20.0.4
[2020-03-24 21:11:41 +0800] [1667] [INFO] Listening at: http://127.0.0.1:4014 (1667)
[2020-03-24 21:11:41 +0800] [1667] [INFO] Using worker: sync
[2020-03-24 21:11:41 +0800] [1670] [INFO] Booting worker with pid: 1670
[2020-03-24 22:14:17 +0800] [1670] [INFO] Parent changed, shutting down: <Worker 1670>
[2020-03-24 22:14:17 +0800] [1670] [INFO] Worker exiting (pid: 1670)
[2020-03-24 22:19:00 +0800] [2067] [INFO] Starting gunicorn 20.0.4
[2020-03-24 22:19:00 +0800] [2067] [INFO] Listening at: http://0.0.0.0:4014 (2067)
[2020-03-24 22:19:00 +0800] [2067] [INFO] Using worker: sync
[2020-03-24 22:19:00 +0800] [2070] [INFO] Booting worker with pid: 2070
[2020-03-25 11:04:39 +0800] [2823] [INFO] Starting gunicorn 20.0.4
[2020-03-25 11:04:39 +0800] [2823] [INFO] Listening at: http://0.0.0.0:4014 (2823)
[2020-03-25 11:04:39 +0800] [2823] [INFO] Using worker: sync
[2020-03-25 11:04:39 +0800] [2826] [INFO] Booting worker with pid: 2826
[2020-03-25 11:43:13 +0800] [3040] [INFO] Starting gunicorn 20.0.4
[2020-03-25 11:43:13 +0800] [3040] [INFO] Listening at: http://0.0.0.0:4014 (3040)
[2020-03-25 11:43:13 +0800] [3040] [INFO] Using worker: sync
[2020-03-25 11:43:13 +0800] [3043] [INFO] Booting worker with pid: 3043
[2020-03-25 11:43:51 +0800] [3061] [INFO] Starting gunicorn 20.0.4
[2020-03-25 11:45:27 +0800] [3114] [INFO] Starting gunicorn 20.0.4
[2020-03-25 11:45:27 +0800] [3114] [INFO] Listening at: http://0.0.0.0:4014 (3114)
[2020-03-25 11:45:27 +0800] [3114] [INFO] Using worker: sync
[2020-03-25 11:45:27 +0800] [3117] [INFO] Booting worker with pid: 3117
[2020-03-25 15:25:36 +0800] [3410] [INFO] Starting gunicorn 20.0.4
[2020-03-25 15:25:36 +0800] [3410] [INFO] Listening at: http://0.0.0.0:4014 (3410)
[2020-03-25 15:25:36 +0800] [3410] [INFO] Using worker: sync
[2020-03-25 15:25:36 +0800] [3413] [INFO] Booting worker with pid: 3413
[2020-03-25 15:52:18 +0800] [3601] [INFO] Starting gunicorn 20.0.4
[2020-03-25 15:52:18 +0800] [3601] [INFO] Listening at: http://0.0.0.0:4014 (3601)
[2020-03-25 15:52:18 +0800] [3601] [INFO] Using worker: sync
[2020-03-25 15:52:18 +0800] [3604] [INFO] Booting worker with pid: 3604
